/*
ASYNC AWAIT

Handling Errors

When .catch() is used with a long promise chain, there is no indication of where in the chain the error was thrown. This can make debugging challenging.

With async...await, we use try...catch statements for error handling. By using this syntax, not only are we able to handle errors in the same way we do with synchronous code, but we can also catch both synchronous and asynchronous errors. This makes for easier debugging!
*/

async function usingTryCatch() {
 try {
   let resolveValue = await asyncFunction('thing that will fail');
   let secondValue = await secondAsyncFunction(resolveValue);
 } catch (err) {
   // Catches any errors in the try block
   console.log(err);
 }
}

usingTryCatch();

/*
Remember, since async functions return promises we can still use native promiseâ€™s .catch() with an async function
*/

async function usingPromiseCatch() {
   let resolveValue = await asyncFunction('thing that will fail');
}

let rejectedPromise = usingPromiseCatch();
rejectedPromise.catch((rejectValue) => {
console.log(rejectValue);
})

//This is sometimes used in the global scope to catch final errors in complex code.


/*
*/


const cookBeanSouffle = require('./library.js');

// Write your code below:
async function hostDinnerParty() {
  try {
    let resolvedValue = await cookBeanSouffle();
    console.log(`${resolvedValue} is served!`);
  } catch (error) {
    console.log(error);
    console.log(`Ordering a pizza!`);
  }
}

hostDinnerParty();


/*
//This function returns true 50% of the time.
let randomSuccess = () => {
 let num = Math.random();
 if (num < .5 ){
   return true;
 } else {
   return false;
 }
};

//This function returns a promise that resolves half of the time and rejects half of the time
let cookBeanSouffle = () => {
 return new Promise((resolve, reject) => {
   console.log('Fingers crossed... Putting the Bean Souffle in the oven');
   setTimeout(()=>{
     let success = randomSuccess();
     if(success){
       resolve('Bean Souffle');
     } else {
       reject('Dinner is ruined!');
     }
   }, 1000);
 })
};

module.exports = cookBeanSouffle;
*/
